NAMESPACE            LAST SEEN   TYPE      REASON                    OBJECT                                                           MESSAGE
kube-system          14m         Normal    LeaderElection            lease/kube-controller-manager                                    article3-performance-control-plane_313f391a-bae2-4e49-8618-a94448b27f73 became leader
default              15m         Normal    NodeHasSufficientMemory   node/article3-performance-control-plane                          Node article3-performance-control-plane status is now: NodeHasSufficientMemory
default              15m         Normal    NodeHasNoDiskPressure     node/article3-performance-control-plane                          Node article3-performance-control-plane status is now: NodeHasNoDiskPressure
default              15m         Normal    NodeHasSufficientPID      node/article3-performance-control-plane                          Node article3-performance-control-plane status is now: NodeHasSufficientPID
default              15m         Normal    Starting                  node/article3-performance-control-plane                          Starting kubelet.
kube-system          15m         Normal    Pulled                    pod/kube-apiserver-article3-performance-control-plane            Container image "registry.k8s.io/kube-apiserver:v1.35.0" already present on machine and can be accessed by the pod
default              15m         Normal    NodeAllocatableEnforced   node/article3-performance-control-plane                          Updated Node Allocatable limit across pods
kube-system          15m         Normal    Pulled                    pod/kube-scheduler-article3-performance-control-plane            Container image "registry.k8s.io/kube-scheduler:v1.35.0" already present on machine and can be accessed by the pod
kube-system          14m         Normal    Started                   pod/kube-scheduler-article3-performance-control-plane            Container started
kube-system          14m         Normal    Started                   pod/kube-apiserver-article3-performance-control-plane            Container started
kube-system          15m         Normal    Pulled                    pod/kube-controller-manager-article3-performance-control-plane   Container image "registry.k8s.io/kube-controller-manager:v1.35.0" already present on machine and can be accessed by the pod
kube-system          14m         Normal    Created                   pod/kube-apiserver-article3-performance-control-plane            Container created
kube-system          14m         Normal    Created                   pod/kube-controller-manager-article3-performance-control-plane   Container created
kube-system          14m         Normal    Created                   pod/etcd-article3-performance-control-plane                      Container created
kube-system          14m         Normal    Started                   pod/etcd-article3-performance-control-plane                      Container started
kube-system          14m         Normal    Created                   pod/kube-scheduler-article3-performance-control-plane            Container created
kube-system          15m         Normal    Pulled                    pod/etcd-article3-performance-control-plane                      Container image "registry.k8s.io/etcd:3.6.6-0" already present on machine and can be accessed by the pod
kube-system          14m         Normal    Started                   pod/kube-controller-manager-article3-performance-control-plane   Container started
kube-system          14m         Normal    LeaderElection            lease/kube-scheduler                                             article3-performance-control-plane_5abf1236-3f3d-4196-9f36-780e18282da3 became leader
default              14m         Normal    Starting                  node/article3-performance-control-plane                          Starting kubelet.
default              14m         Normal    NodeAllocatableEnforced   node/article3-performance-control-plane                          Updated Node Allocatable limit across pods
default              14m         Normal    NodeHasSufficientPID      node/article3-performance-control-plane                          Node article3-performance-control-plane status is now: NodeHasSufficientPID
default              14m         Normal    NodeHasNoDiskPressure     node/article3-performance-control-plane                          Node article3-performance-control-plane status is now: NodeHasNoDiskPressure
default              14m         Normal    NodeHasSufficientMemory   node/article3-performance-control-plane                          Node article3-performance-control-plane status is now: NodeHasSufficientMemory
default              14m         Normal    RegisteredNode            node/article3-performance-control-plane                          Node article3-performance-control-plane event: Registered Node article3-performance-control-plane in Controller
kube-system          116s        Warning   Unhealthy                 pod/kube-apiserver-article3-performance-control-plane            Readiness probe failed: HTTP probe failed with statuscode: 500
kube-system          14m         Warning   Unhealthy                 pod/kube-controller-manager-article3-performance-control-plane   Startup probe failed: Get "https://127.0.0.1:10257/healthz": unexpected EOF
kube-system          2m48s       Normal    Pulled                    pod/kube-controller-manager-article3-performance-control-plane   Container image "registry.k8s.io/kube-controller-manager:v1.35.0" already present on machine and can be accessed by the pod
kube-system          14m         Normal    LeaderElection            lease/kube-scheduler                                             article3-performance-control-plane_5abf1236-3f3d-4196-9f36-780e18282da3 stopped leading
kube-system          14m         Warning   Unhealthy                 pod/kube-apiserver-article3-performance-control-plane            Startup probe failed: HTTP probe failed with statuscode: 500
kube-system          112s        Warning   Unhealthy                 pod/kube-scheduler-article3-performance-control-plane            Readiness probe failed: Get "https://127.0.0.1:10259/readyz": dial tcp 127.0.0.1:10259: connect: connection refused
kube-system          2m48s       Normal    Created                   pod/kube-controller-manager-article3-performance-control-plane   Container created
kube-system          5m3s        Normal    Pulled                    pod/kube-scheduler-article3-performance-control-plane            Container image "registry.k8s.io/kube-scheduler:v1.35.0" already present on machine and can be accessed by the pod
kube-system          5m3s        Normal    Created                   pod/kube-scheduler-article3-performance-control-plane            Container created
kube-system          2m47s       Normal    Started                   pod/kube-controller-manager-article3-performance-control-plane   Container started
kube-system          5m3s        Normal    Started                   pod/kube-scheduler-article3-performance-control-plane            Container started
kube-system          14m         Normal    LeaderElection            lease/kube-scheduler                                             article3-performance-control-plane_16a5dffa-8e0d-4add-9afb-004cfbbfc0bc became leader
kube-system          14m         Normal    LeaderElection            lease/kube-controller-manager                                    article3-performance-control-plane_930ea90c-4384-41e6-bbc3-628f6d34ad62 became leader
kube-system          118s        Warning   Unhealthy                 pod/kube-controller-manager-article3-performance-control-plane   Liveness probe failed: Get "https://127.0.0.1:10257/healthz": dial tcp 127.0.0.1:10257: connect: connection refused
kube-system          41s         Warning   BackOff                   pod/kube-controller-manager-article3-performance-control-plane   Back-off restarting failed container kube-controller-manager in pod kube-controller-manager-article3-performance-control-plane_kube-system(d6355cfce5e6c4cb2f4171c133abd18a)
kube-system          13m         Normal    LeaderElection            lease/kube-controller-manager                                    article3-performance-control-plane_bfd39900-0bf1-4403-9a2e-115addddaf3a became leader
default              13m         Normal    RegisteredNode            node/article3-performance-control-plane                          Node article3-performance-control-plane event: Registered Node article3-performance-control-plane in Controller
kube-system          13m         Normal    SuccessfulCreate          daemonset/kube-proxy                                             Created pod: kube-proxy-9njtm
local-path-storage   13m         Normal    ScalingReplicaSet         deployment/local-path-provisioner                                Scaled up replica set local-path-provisioner-67b8995b4b from 0 to 1
kube-system          13m         Normal    SuccessfulCreate          replicaset/coredns-7d764666f9                                    Created pod: coredns-7d764666f9-nqhpp
local-path-storage   13m         Normal    SuccessfulCreate          replicaset/local-path-provisioner-67b8995b4b                     Created pod: local-path-provisioner-67b8995b4b-dpcz4
kube-system          13m         Normal    SuccessfulCreate          replicaset/coredns-7d764666f9                                    Created pod: coredns-7d764666f9-lqg4p
kube-system          13m         Warning   FailedScheduling          pod/coredns-7d764666f9-nqhpp                                     0/1 nodes are available: 1 node(s) had untolerated taint(s). no new claims to deallocate, preemption: 0/1 nodes are available: 1 Preemption is not helpful for scheduling.
kube-system          13m         Warning   FailedScheduling          pod/coredns-7d764666f9-lqg4p                                     0/1 nodes are available: 1 node(s) had untolerated taint(s). no new claims to deallocate, preemption: 0/1 nodes are available: 1 Preemption is not helpful for scheduling.
local-path-storage   13m         Warning   FailedScheduling          pod/local-path-provisioner-67b8995b4b-dpcz4                      0/1 nodes are available: 1 node(s) had untolerated taint(s). no new claims to deallocate, preemption: 0/1 nodes are available: 1 Preemption is not helpful for scheduling.
kube-system          13m         Normal    Scheduled                 pod/kube-proxy-9njtm                                             Successfully assigned kube-system/kube-proxy-9njtm to article3-performance-control-plane
kube-system          13m         Normal    Pulled                    pod/kube-proxy-9njtm                                             Container image "registry.k8s.io/kube-proxy:v1.35.0" already present on machine and can be accessed by the pod
kube-system          12m         Normal    SuccessfulCreate          daemonset/kube-proxy                                             Created pod: kube-proxy-dzfrp
kube-system          12m         Normal    SuccessfulCreate          daemonset/kube-proxy                                             Created pod: kube-proxy-5vbtx
default              12m         Normal    RegisteredNode            node/article3-performance-worker                                 Node article3-performance-worker event: Registered Node article3-performance-worker in Controller
kube-system          12m         Normal    SuccessfulCreate          daemonset/kube-proxy                                             Created pod: kube-proxy-f8vhr
default              12m         Normal    RegisteredNode            node/article3-performance-worker3                                Node article3-performance-worker3 event: Registered Node article3-performance-worker3 in Controller
default              12m         Normal    RegisteredNode            node/article3-performance-worker2                                Node article3-performance-worker2 event: Registered Node article3-performance-worker2 in Controller
kube-system          12m         Normal    Scheduled                 pod/kube-proxy-5vbtx                                             Successfully assigned kube-system/kube-proxy-5vbtx to article3-performance-worker2
kube-system          12m         Normal    Scheduled                 pod/kube-proxy-dzfrp                                             Successfully assigned kube-system/kube-proxy-dzfrp to article3-performance-worker3
kube-system          12m         Normal    Scheduled                 pod/kube-proxy-f8vhr                                             Successfully assigned kube-system/kube-proxy-f8vhr to article3-performance-worker
kube-system          12m         Normal    Created                   pod/kube-proxy-9njtm                                             Container created
kube-system          12m         Normal    Pulled                    pod/kube-proxy-dzfrp                                             Container image "registry.k8s.io/kube-proxy:v1.35.0" already present on machine and can be accessed by the pod
kube-system          12m         Normal    Started                   pod/kube-proxy-9njtm                                             Container started
kube-system          12m         Normal    Created                   pod/kube-proxy-dzfrp                                             Container created
kube-system          12m         Warning   FailedMount               pod/kube-proxy-f8vhr                                             MountVolume.SetUp failed for volume "kube-proxy" : failed to sync configmap cache: timed out waiting for the condition
kube-system          12m         Normal    Started                   pod/kube-proxy-dzfrp                                             Container started
kube-system          12m         Normal    LeaderElection            lease/kube-scheduler                                             article3-performance-control-plane_16a5dffa-8e0d-4add-9afb-004cfbbfc0bc stopped leading
kube-system          12m         Normal    Pulled                    pod/kube-proxy-f8vhr                                             Container image "registry.k8s.io/kube-proxy:v1.35.0" already present on machine and can be accessed by the pod
kube-system          12m         Warning   Unhealthy                 pod/kube-controller-manager-article3-performance-control-plane   Liveness probe failed: Get "https://127.0.0.1:10257/healthz": read tcp 127.0.0.1:33008->127.0.0.1:10257: read: connection reset by peer
kube-system          12m         Warning   FailedMount               pod/kube-proxy-5vbtx                                             MountVolume.SetUp failed for volume "kube-proxy" : failed to sync configmap cache: timed out waiting for the condition
kube-system          117s        Warning   Unhealthy                 pod/kube-apiserver-article3-performance-control-plane            Liveness probe failed: HTTP probe failed with statuscode: 500
default              12m         Normal    Starting                  node/article3-performance-worker3                                
kube-system          8m48s       Warning   BackOff                   pod/kube-scheduler-article3-performance-control-plane            Back-off restarting failed container kube-scheduler in pod kube-scheduler-article3-performance-control-plane_kube-system(38013c1ff7595ecbb6a654827d4a784f)
kube-system          12m         Normal    Pulled                    pod/kube-proxy-5vbtx                                             Container image "registry.k8s.io/kube-proxy:v1.35.0" already present on machine and can be accessed by the pod
kube-system          12m         Normal    Created                   pod/kube-proxy-f8vhr                                             Container created
kube-system          12m         Normal    Created                   pod/kube-proxy-5vbtx                                             Container created
kube-system          12m         Normal    Started                   pod/kube-proxy-f8vhr                                             Container started
kube-system          12m         Normal    Started                   pod/kube-proxy-5vbtx                                             Container started
default              11m         Normal    Starting                  node/article3-performance-worker                                 
default              11m         Normal    Starting                  node/article3-performance-worker2                                
kube-system          7m45s       Warning   Unhealthy                 pod/kube-scheduler-article3-performance-control-plane            Startup probe failed: Get "https://127.0.0.1:10259/livez": dial tcp 127.0.0.1:10259: connect: connection refused
kube-system          6m13s       Warning   Unhealthy                 pod/kube-controller-manager-article3-performance-control-plane   Startup probe failed: Get "https://127.0.0.1:10257/healthz": dial tcp 127.0.0.1:10257: connect: connection refused
kube-system          11m         Warning   Unhealthy                 pod/kube-apiserver-article3-performance-control-plane            Readiness probe failed: Get "https://172.18.0.11:6443/readyz": net/http: request canceled (Client.Timeout exceeded while awaiting headers)
kube-system          11m         Warning   Unhealthy                 pod/kube-scheduler-article3-performance-control-plane            Startup probe failed: Get "https://127.0.0.1:10259/livez": net/http: TLS handshake timeout
kube-system          10m         Warning   Unhealthy                 pod/kube-scheduler-article3-performance-control-plane            Readiness probe failed: HTTP probe failed with statuscode: 500
kube-system          10m         Normal    LeaderElection            lease/kube-controller-manager                                    article3-performance-control-plane_e7e92761-0794-4f8d-93ea-63f0badb60ba became leader
default              10m         Normal    Starting                  node/article3-performance-control-plane                          
kube-system          10m         Normal    LeaderElection            lease/kube-scheduler                                             article3-performance-control-plane_b68ec26c-0670-4434-b863-16014bf0a636 became leader
kube-system          10m         Warning   FailedScheduling          pod/coredns-7d764666f9-lqg4p                                     0/4 nodes are available: 4 node(s) had untolerated taint(s). no new claims to deallocate, preemption: 0/4 nodes are available: 4 Preemption is not helpful for scheduling.
kube-system          10m         Warning   FailedScheduling          pod/coredns-7d764666f9-nqhpp                                     0/4 nodes are available: 4 node(s) had untolerated taint(s). no new claims to deallocate, preemption: 0/4 nodes are available: 4 Preemption is not helpful for scheduling.
local-path-storage   10m         Warning   FailedScheduling          pod/local-path-provisioner-67b8995b4b-dpcz4                      0/4 nodes are available: 4 node(s) had untolerated taint(s). no new claims to deallocate, preemption: 0/4 nodes are available: 4 Preemption is not helpful for scheduling.
kube-system          10m         Warning   Unhealthy                 pod/kube-scheduler-article3-performance-control-plane            Liveness probe failed: Get "https://127.0.0.1:10259/livez": dial tcp 127.0.0.1:10259: connect: connection refused
kube-system          9m26s       Warning   FailedScheduling          pod/coredns-7d764666f9-lqg4p                                     0/4 nodes are available: 4 node(s) had untolerated taint(s). no new claims to deallocate, preemption: 0/4 nodes are available: 4 Preemption is not helpful for scheduling.
local-path-storage   9m26s       Warning   FailedScheduling          pod/local-path-provisioner-67b8995b4b-dpcz4                      0/4 nodes are available: 4 node(s) had untolerated taint(s). no new claims to deallocate, preemption: 0/4 nodes are available: 4 Preemption is not helpful for scheduling.
kube-system          9m26s       Warning   FailedScheduling          pod/coredns-7d764666f9-nqhpp                                     0/4 nodes are available: 4 node(s) had untolerated taint(s). no new claims to deallocate, preemption: 0/4 nodes are available: 4 Preemption is not helpful for scheduling.
kube-system          9m26s       Normal    LeaderElection            lease/kube-scheduler                                             article3-performance-control-plane_4a93ce98-c84b-40f8-ad6e-c0778adfaa04 became leader
kube-system          8m53s       Warning   Unhealthy                 pod/kube-controller-manager-article3-performance-control-plane   Startup probe failed: Get "https://127.0.0.1:10257/healthz": net/http: TLS handshake timeout
kube-system          8m35s       Normal    LeaderElection            lease/kube-controller-manager                                    article3-performance-control-plane_1b023fe9-41a1-4dd9-9c75-8fff45e78265 became leader
kube-system          8m17s       Warning   Unhealthy                 pod/kube-controller-manager-article3-performance-control-plane   Liveness probe failed: Get "https://127.0.0.1:10257/healthz": unexpected EOF
kube-system          7m26s       Warning   FailedScheduling          pod/coredns-7d764666f9-nqhpp                                     0/4 nodes are available: 4 node(s) had untolerated taint(s). no new claims to deallocate, preemption: 0/4 nodes are available: 4 Preemption is not helpful for scheduling.
kube-system          7m26s       Normal    LeaderElection            lease/kube-scheduler                                             article3-performance-control-plane_551de8d7-50f7-4005-a98d-037ce9981c64 became leader
kube-system          7m26s       Warning   FailedScheduling          pod/coredns-7d764666f9-lqg4p                                     0/4 nodes are available: 4 node(s) had untolerated taint(s). no new claims to deallocate, preemption: 0/4 nodes are available: 4 Preemption is not helpful for scheduling.
local-path-storage   7m26s       Warning   FailedScheduling          pod/local-path-provisioner-67b8995b4b-dpcz4                      0/4 nodes are available: 4 node(s) had untolerated taint(s). no new claims to deallocate, preemption: 0/4 nodes are available: 4 Preemption is not helpful for scheduling.
kube-system          5m54s       Normal    LeaderElection            lease/kube-controller-manager                                    article3-performance-control-plane_c0b79080-d737-4850-9303-b3fb5adbd69a became leader
default              5m52s       Normal    RegisteredNode            node/article3-performance-worker                                 Node article3-performance-worker event: Registered Node article3-performance-worker in Controller
default              5m52s       Normal    RegisteredNode            node/article3-performance-worker2                                Node article3-performance-worker2 event: Registered Node article3-performance-worker2 in Controller
default              5m52s       Normal    RegisteredNode            node/article3-performance-control-plane                          Node article3-performance-control-plane event: Registered Node article3-performance-control-plane in Controller
default              5m52s       Normal    RegisteredNode            node/article3-performance-worker3                                Node article3-performance-worker3 event: Registered Node article3-performance-worker3 in Controller
kube-system          5m2s        Warning   FailedScheduling          pod/coredns-7d764666f9-nqhpp                                     0/4 nodes are available: 4 node(s) had untolerated taint(s). no new claims to deallocate, preemption: 0/4 nodes are available: 4 Preemption is not helpful for scheduling.
kube-system          5m2s        Normal    LeaderElection            lease/kube-scheduler                                             article3-performance-control-plane_50bf9398-cd90-4621-b31f-37ca8ba79816 became leader
local-path-storage   5m2s        Warning   FailedScheduling          pod/local-path-provisioner-67b8995b4b-dpcz4                      0/4 nodes are available: 4 node(s) had untolerated taint(s). no new claims to deallocate, preemption: 0/4 nodes are available: 4 Preemption is not helpful for scheduling.
kube-system          5m2s        Warning   FailedScheduling          pod/coredns-7d764666f9-lqg4p                                     0/4 nodes are available: 4 node(s) had untolerated taint(s). no new claims to deallocate, preemption: 0/4 nodes are available: 4 Preemption is not helpful for scheduling.
kube-system          2m27s       Normal    LeaderElection            lease/kube-controller-manager                                    article3-performance-control-plane_e43a88c1-f0d3-4499-b466-1bd34d8c1fe4 became leader
default              2m25s       Normal    RegisteredNode            node/article3-performance-worker3                                Node article3-performance-worker3 event: Registered Node article3-performance-worker3 in Controller
default              2m25s       Normal    RegisteredNode            node/article3-performance-control-plane                          Node article3-performance-control-plane event: Registered Node article3-performance-control-plane in Controller
default              2m25s       Normal    RegisteredNode            node/article3-performance-worker2                                Node article3-performance-worker2 event: Registered Node article3-performance-worker2 in Controller
default              2m25s       Normal    RegisteredNode            node/article3-performance-worker                                 Node article3-performance-worker event: Registered Node article3-performance-worker in Controller
kube-system          114s        Normal    LeaderElection            lease/kube-scheduler                                             article3-performance-control-plane_50bf9398-cd90-4621-b31f-37ca8ba79816 stopped leading
