NAMESPACE            LAST SEEN   TYPE      REASON                    OBJECT                                                           MESSAGE
default              9m44s       Normal    Starting                  node/article3-performance-control-plane                          Starting kubelet.
default              9m43s       Normal    NodeAllocatableEnforced   node/article3-performance-control-plane                          Updated Node Allocatable limit across pods
default              9m43s       Normal    NodeHasSufficientPID      node/article3-performance-control-plane                          Node article3-performance-control-plane status is now: NodeHasSufficientPID
default              9m43s       Normal    NodeHasNoDiskPressure     node/article3-performance-control-plane                          Node article3-performance-control-plane status is now: NodeHasNoDiskPressure
default              9m43s       Normal    NodeHasSufficientMemory   node/article3-performance-control-plane                          Node article3-performance-control-plane status is now: NodeHasSufficientMemory
kube-system          9m38s       Normal    Started                   pod/etcd-article3-performance-control-plane                      Container started
kube-system          9m39s       Normal    Created                   pod/kube-apiserver-article3-performance-control-plane            Container created
kube-system          9m39s       Normal    Created                   pod/kube-scheduler-article3-performance-control-plane            Container created
kube-system          9m42s       Normal    Pulled                    pod/kube-scheduler-article3-performance-control-plane            Container image "registry.k8s.io/kube-scheduler:v1.35.0" already present on machine and can be accessed by the pod
kube-system          9m42s       Normal    Pulled                    pod/etcd-article3-performance-control-plane                      Container image "registry.k8s.io/etcd:3.6.6-0" already present on machine and can be accessed by the pod
kube-system          9m38s       Normal    Started                   pod/kube-controller-manager-article3-performance-control-plane   Container started
kube-system          9m39s       Normal    Created                   pod/kube-controller-manager-article3-performance-control-plane   Container created
kube-system          9m38s       Normal    Created                   pod/etcd-article3-performance-control-plane                      Container created
kube-system          9m38s       Normal    Started                   pod/kube-scheduler-article3-performance-control-plane            Container started
kube-system          9m42s       Normal    Pulled                    pod/kube-apiserver-article3-performance-control-plane            Container image "registry.k8s.io/kube-apiserver:v1.35.0" already present on machine and can be accessed by the pod
kube-system          9m42s       Normal    Pulled                    pod/kube-controller-manager-article3-performance-control-plane   Container image "registry.k8s.io/kube-controller-manager:v1.35.0" already present on machine and can be accessed by the pod
kube-system          9m38s       Normal    Started                   pod/kube-apiserver-article3-performance-control-plane            Container started
kube-system          9m32s       Normal    LeaderElection            lease/kube-controller-manager                                    article3-performance-control-plane_02098948-1deb-42ab-8aec-ce40755aa1f7 became leader
default              9m31s       Normal    NodeAllocatableEnforced   node/article3-performance-control-plane                          Updated Node Allocatable limit across pods
default              9m31s       Normal    NodeHasSufficientPID      node/article3-performance-control-plane                          Node article3-performance-control-plane status is now: NodeHasSufficientPID
default              9m31s       Normal    NodeHasNoDiskPressure     node/article3-performance-control-plane                          Node article3-performance-control-plane status is now: NodeHasNoDiskPressure
default              9m31s       Normal    NodeHasSufficientMemory   node/article3-performance-control-plane                          Node article3-performance-control-plane status is now: NodeHasSufficientMemory
default              9m31s       Normal    Starting                  node/article3-performance-control-plane                          Starting kubelet.
kube-system          9m29s       Warning   Unhealthy                 pod/kube-scheduler-article3-performance-control-plane            Readiness probe failed: HTTP probe failed with statuscode: 500
kube-system          9m29s       Normal    LeaderElection            lease/kube-scheduler                                             article3-performance-control-plane_ead147f3-44c9-49ec-94bc-1c9357ca47d0 became leader
default              9m27s       Normal    RegisteredNode            node/article3-performance-control-plane                          Node article3-performance-control-plane event: Registered Node article3-performance-control-plane in Controller
kube-system          9m26s       Warning   FailedScheduling          pod/coredns-7d764666f9-d44n9                                     0/1 nodes are available: 1 node(s) had untolerated taint(s). no new claims to deallocate, preemption: 0/1 nodes are available: 1 Preemption is not helpful for scheduling.
kube-system          9m26s       Normal    SuccessfulCreate          replicaset/coredns-7d764666f9                                    Created pod: coredns-7d764666f9-j5lb8
kube-system          9m26s       Normal    Scheduled                 pod/kube-proxy-pcpql                                             Successfully assigned kube-system/kube-proxy-pcpql to article3-performance-control-plane
local-path-storage   9m26s       Normal    ScalingReplicaSet         deployment/local-path-provisioner                                Scaled up replica set local-path-provisioner-67b8995b4b from 0 to 1
local-path-storage   9m26s       Normal    SuccessfulCreate          replicaset/local-path-provisioner-67b8995b4b                     Created pod: local-path-provisioner-67b8995b4b-7hc8p
local-path-storage   9m26s       Warning   FailedScheduling          pod/local-path-provisioner-67b8995b4b-7hc8p                      0/1 nodes are available: 1 node(s) had untolerated taint(s). no new claims to deallocate, preemption: 0/1 nodes are available: 1 Preemption is not helpful for scheduling.
kube-system          9m26s       Normal    SuccessfulCreate          daemonset/kube-proxy                                             Created pod: kube-proxy-pcpql
kube-system          9m26s       Normal    ScalingReplicaSet         deployment/coredns                                               Scaled up replica set coredns-7d764666f9 from 0 to 2
kube-system          9m26s       Normal    SuccessfulCreate          replicaset/coredns-7d764666f9                                    Created pod: coredns-7d764666f9-d44n9
kube-system          9m26s       Warning   FailedScheduling          pod/coredns-7d764666f9-j5lb8                                     0/1 nodes are available: 1 node(s) had untolerated taint(s). no new claims to deallocate, preemption: 0/1 nodes are available: 1 Preemption is not helpful for scheduling.
kube-system          9m25s       Normal    Pulled                    pod/kube-proxy-pcpql                                             Container image "registry.k8s.io/kube-proxy:v1.35.0" already present on machine and can be accessed by the pod
kube-system          9m24s       Normal    Created                   pod/kube-proxy-pcpql                                             Container created
kube-system          9m24s       Normal    Started                   pod/kube-proxy-pcpql                                             Container started
default              9m22s       Normal    Starting                  node/article3-performance-control-plane                          
default              9m22s       Normal    NodeHasNoDiskPressure     node/article3-performance-worker3                                Node article3-performance-worker3 status is now: NodeHasNoDiskPressure
default              9m22s       Normal    NodeHasSufficientPID      node/article3-performance-worker3                                Node article3-performance-worker3 status is now: NodeHasSufficientPID
default              9m22s       Normal    NodeHasSufficientMemory   node/article3-performance-worker3                                Node article3-performance-worker3 status is now: NodeHasSufficientMemory
default              9m23s       Normal    Starting                  node/article3-performance-worker3                                Starting kubelet.
default              9m22s       Normal    RegisteredNode            node/article3-performance-worker3                                Node article3-performance-worker3 event: Registered Node article3-performance-worker3 in Controller
default              9m22s       Normal    RegisteredNode            node/article3-performance-worker                                 Node article3-performance-worker event: Registered Node article3-performance-worker in Controller
default              9m22s       Normal    NodeHasNoDiskPressure     node/article3-performance-worker                                 Node article3-performance-worker status is now: NodeHasNoDiskPressure
default              9m22s       Normal    NodeHasSufficientMemory   node/article3-performance-worker                                 Node article3-performance-worker status is now: NodeHasSufficientMemory
kube-system          9m22s       Normal    SuccessfulCreate          daemonset/kube-proxy                                             Created pod: kube-proxy-rc8tf
kube-system          9m22s       Normal    SuccessfulCreate          daemonset/kube-proxy                                             Created pod: kube-proxy-7blbs
kube-system          9m22s       Normal    SuccessfulCreate          daemonset/kube-proxy                                             Created pod: kube-proxy-5v8gc
kube-system          9m22s       Normal    Scheduled                 pod/kube-proxy-7blbs                                             Successfully assigned kube-system/kube-proxy-7blbs to article3-performance-worker2
default              9m22s       Normal    NodeAllocatableEnforced   node/article3-performance-worker3                                Updated Node Allocatable limit across pods
default              9m22s       Normal    RegisteredNode            node/article3-performance-worker2                                Node article3-performance-worker2 event: Registered Node article3-performance-worker2 in Controller
default              9m22s       Normal    NodeAllocatableEnforced   node/article3-performance-worker2                                Updated Node Allocatable limit across pods
default              9m22s       Normal    NodeHasSufficientPID      node/article3-performance-worker2                                Node article3-performance-worker2 status is now: NodeHasSufficientPID
default              9m22s       Normal    NodeHasNoDiskPressure     node/article3-performance-worker2                                Node article3-performance-worker2 status is now: NodeHasNoDiskPressure
kube-system          9m22s       Normal    Scheduled                 pod/kube-proxy-5v8gc                                             Successfully assigned kube-system/kube-proxy-5v8gc to article3-performance-worker3
default              9m22s       Normal    Starting                  node/article3-performance-worker                                 Starting kubelet.
default              9m22s       Normal    NodeHasSufficientMemory   node/article3-performance-worker2                                Node article3-performance-worker2 status is now: NodeHasSufficientMemory
kube-system          9m22s       Normal    Scheduled                 pod/kube-proxy-rc8tf                                             Successfully assigned kube-system/kube-proxy-rc8tf to article3-performance-worker
default              9m22s       Normal    NodeHasSufficientPID      node/article3-performance-worker                                 Node article3-performance-worker status is now: NodeHasSufficientPID
default              9m22s       Normal    NodeAllocatableEnforced   node/article3-performance-worker                                 Updated Node Allocatable limit across pods
kube-system          9m21s       Normal    Pulled                    pod/kube-proxy-rc8tf                                             Container image "registry.k8s.io/kube-proxy:v1.35.0" already present on machine and can be accessed by the pod
kube-system          9m21s       Normal    Pulled                    pod/kube-proxy-5v8gc                                             Container image "registry.k8s.io/kube-proxy:v1.35.0" already present on machine and can be accessed by the pod
kube-system          9m19s       Normal    Pulled                    pod/kube-proxy-7blbs                                             Container image "registry.k8s.io/kube-proxy:v1.35.0" already present on machine and can be accessed by the pod
kube-system          9m19s       Normal    Created                   pod/kube-proxy-rc8tf                                             Container created
kube-system          9m19s       Normal    Created                   pod/kube-proxy-5v8gc                                             Container created
kube-system          9m19s       Normal    Started                   pod/kube-proxy-5v8gc                                             Container started
default              9m17s       Normal    Starting                  node/article3-performance-worker                                 
default              9m17s       Normal    Starting                  node/article3-performance-worker3                                
kube-system          9m18s       Normal    Started                   pod/kube-proxy-rc8tf                                             Container started
kube-system          9m17s       Normal    Created                   pod/kube-proxy-7blbs                                             Container created
kube-system          9m17s       Normal    Started                   pod/kube-proxy-7blbs                                             Container started
default              9m15s       Normal    Starting                  node/article3-performance-worker2                                
kube-system          3m58s       Warning   FailedScheduling          pod/coredns-7d764666f9-d44n9                                     0/4 nodes are available: 4 node(s) had untolerated taint(s). no new claims to deallocate, preemption: 0/4 nodes are available: 4 Preemption is not helpful for scheduling.
local-path-storage   3m58s       Warning   FailedScheduling          pod/local-path-provisioner-67b8995b4b-7hc8p                      0/4 nodes are available: 4 node(s) had untolerated taint(s). no new claims to deallocate, preemption: 0/4 nodes are available: 4 Preemption is not helpful for scheduling.
kube-system          3m58s       Warning   FailedScheduling          pod/coredns-7d764666f9-j5lb8                                     0/4 nodes are available: 4 node(s) had untolerated taint(s). no new claims to deallocate, preemption: 0/4 nodes are available: 4 Preemption is not helpful for scheduling.
kube-system          56s         Normal    NoPods                    poddisruptionbudget/calico-kube-controllers                      No matching pods found
kube-system          55s         Normal    Scheduled                 pod/calico-node-hfqqw                                            Successfully assigned kube-system/calico-node-hfqqw to article3-performance-control-plane
kube-system          55s         Normal    SuccessfulCreate          daemonset/calico-node                                            Created pod: calico-node-blglx
kube-system          55s         Warning   FailedScheduling          pod/calico-kube-controllers-77bdb5dddb-mnzxq                     0/4 nodes are available: 4 node(s) had untolerated taint(s). no new claims to deallocate, preemption: 0/4 nodes are available: 4 Preemption is not helpful for scheduling.
kube-system          55s         Normal    SuccessfulCreate          replicaset/calico-kube-controllers-77bdb5dddb                    Created pod: calico-kube-controllers-77bdb5dddb-mnzxq
kube-system          55s         Normal    SuccessfulCreate          daemonset/calico-node                                            Created pod: calico-node-c2jhk
kube-system          55s         Normal    Scheduled                 pod/calico-node-nmr4f                                            Successfully assigned kube-system/calico-node-nmr4f to article3-performance-worker2
kube-system          55s         Normal    SuccessfulCreate          daemonset/calico-node                                            Created pod: calico-node-hfqqw
kube-system          55s         Normal    SuccessfulCreate          daemonset/calico-node                                            Created pod: calico-node-nmr4f
kube-system          55s         Normal    ScalingReplicaSet         deployment/calico-kube-controllers                               Scaled up replica set calico-kube-controllers-77bdb5dddb from 0 to 1
kube-system          55s         Normal    Scheduled                 pod/calico-node-blglx                                            Successfully assigned kube-system/calico-node-blglx to article3-performance-worker
kube-system          55s         Normal    Scheduled                 pod/calico-node-c2jhk                                            Successfully assigned kube-system/calico-node-c2jhk to article3-performance-worker3
kube-system          54s         Normal    Created                   pod/calico-node-hfqqw                                            Container created
kube-system          54s         Normal    Started                   pod/calico-node-blglx                                            Container started
kube-system          54s         Normal    Created                   pod/calico-node-blglx                                            Container created
kube-system          54s         Normal    Created                   pod/calico-node-c2jhk                                            Container created
kube-system          54s         Normal    Pulled                    pod/calico-node-c2jhk                                            Container image "quay.io/calico/cni@sha256:bb1567e3ed81e2e8414e9a68f186e1f7ffd4067a4871a9ae90896793af0190dd" already present on machine and can be accessed by the pod
kube-system          54s         Normal    Pulled                    pod/calico-node-blglx                                            Container image "quay.io/calico/cni@sha256:bb1567e3ed81e2e8414e9a68f186e1f7ffd4067a4871a9ae90896793af0190dd" already present on machine and can be accessed by the pod
kube-system          54s         Normal    Started                   pod/calico-node-hfqqw                                            Container started
kube-system          54s         Normal    Pulled                    pod/calico-node-hfqqw                                            Container image "quay.io/calico/cni@sha256:bb1567e3ed81e2e8414e9a68f186e1f7ffd4067a4871a9ae90896793af0190dd" already present on machine and can be accessed by the pod
kube-system          54s         Normal    Pulled                    pod/calico-node-nmr4f                                            Container image "quay.io/calico/cni@sha256:bb1567e3ed81e2e8414e9a68f186e1f7ffd4067a4871a9ae90896793af0190dd" already present on machine and can be accessed by the pod
kube-system          54s         Normal    Created                   pod/calico-node-nmr4f                                            Container created
kube-system          54s         Normal    Started                   pod/calico-node-nmr4f                                            Container started
kube-system          54s         Normal    Started                   pod/calico-node-c2jhk                                            Container started
kube-system          52s         Normal    Created                   pod/calico-node-blglx                                            Container created
kube-system          52s         Normal    Pulled                    pod/calico-node-blglx                                            Container image "quay.io/calico/cni@sha256:bb1567e3ed81e2e8414e9a68f186e1f7ffd4067a4871a9ae90896793af0190dd" already present on machine and can be accessed by the pod
kube-system          52s         Normal    Created                   pod/calico-node-c2jhk                                            Container created
kube-system          52s         Normal    Pulled                    pod/calico-node-c2jhk                                            Container image "quay.io/calico/cni@sha256:bb1567e3ed81e2e8414e9a68f186e1f7ffd4067a4871a9ae90896793af0190dd" already present on machine and can be accessed by the pod
kube-system          52s         Normal    Pulled                    pod/calico-node-hfqqw                                            Container image "quay.io/calico/cni@sha256:bb1567e3ed81e2e8414e9a68f186e1f7ffd4067a4871a9ae90896793af0190dd" already present on machine and can be accessed by the pod
kube-system          52s         Normal    Created                   pod/calico-node-hfqqw                                            Container created
kube-system          52s         Normal    Started                   pod/calico-node-nmr4f                                            Container started
kube-system          52s         Normal    Started                   pod/calico-node-blglx                                            Container started
kube-system          52s         Normal    Started                   pod/calico-node-c2jhk                                            Container started
kube-system          52s         Normal    Created                   pod/calico-node-nmr4f                                            Container created
kube-system          52s         Normal    Pulled                    pod/calico-node-nmr4f                                            Container image "quay.io/calico/cni@sha256:bb1567e3ed81e2e8414e9a68f186e1f7ffd4067a4871a9ae90896793af0190dd" already present on machine and can be accessed by the pod
kube-system          52s         Normal    Started                   pod/calico-node-hfqqw                                            Container started
kube-system          48s         Normal    Pulled                    pod/calico-node-blglx                                            Container image "quay.io/calico/node@sha256:7f874b3f0b540c2b523aea9961ef5e2f43b0af9056a47874c916d6cf348168d3" already present on machine and can be accessed by the pod
kube-system          48s         Normal    Started                   pod/calico-node-hfqqw                                            Container started
kube-system          48s         Normal    Created                   pod/calico-node-hfqqw                                            Container created
kube-system          48s         Normal    Pulled                    pod/calico-node-hfqqw                                            Container image "quay.io/calico/node@sha256:7f874b3f0b540c2b523aea9961ef5e2f43b0af9056a47874c916d6cf348168d3" already present on machine and can be accessed by the pod
kube-system          48s         Normal    Started                   pod/calico-node-blglx                                            Container started
kube-system          48s         Normal    Created                   pod/calico-node-blglx                                            Container created
kube-system          48s         Normal    Started                   pod/calico-node-nmr4f                                            Container started
kube-system          48s         Normal    Created                   pod/calico-node-nmr4f                                            Container created
kube-system          48s         Normal    Pulled                    pod/calico-node-nmr4f                                            Container image "quay.io/calico/node@sha256:7f874b3f0b540c2b523aea9961ef5e2f43b0af9056a47874c916d6cf348168d3" already present on machine and can be accessed by the pod
kube-system          47s         Normal    Created                   pod/calico-node-c2jhk                                            Container created
kube-system          47s         Normal    Pulled                    pod/calico-node-c2jhk                                            Container image "quay.io/calico/node@sha256:7f874b3f0b540c2b523aea9961ef5e2f43b0af9056a47874c916d6cf348168d3" already present on machine and can be accessed by the pod
kube-system          47s         Normal    Started                   pod/calico-node-c2jhk                                            Container started
kube-system          46s         Normal    Started                   pod/calico-node-nmr4f                                            Container started
kube-system          46s         Normal    Pulled                    pod/calico-node-blglx                                            Container image "quay.io/calico/node@sha256:7f874b3f0b540c2b523aea9961ef5e2f43b0af9056a47874c916d6cf348168d3" already present on machine and can be accessed by the pod
kube-system          46s         Normal    Created                   pod/calico-node-blglx                                            Container created
kube-system          46s         Normal    Started                   pod/calico-node-blglx                                            Container started
kube-system          46s         Normal    Pulled                    pod/calico-node-hfqqw                                            Container image "quay.io/calico/node@sha256:7f874b3f0b540c2b523aea9961ef5e2f43b0af9056a47874c916d6cf348168d3" already present on machine and can be accessed by the pod
kube-system          46s         Normal    Created                   pod/calico-node-hfqqw                                            Container created
kube-system          46s         Normal    Started                   pod/calico-node-hfqqw                                            Container started
kube-system          46s         Normal    Pulled                    pod/calico-node-nmr4f                                            Container image "quay.io/calico/node@sha256:7f874b3f0b540c2b523aea9961ef5e2f43b0af9056a47874c916d6cf348168d3" already present on machine and can be accessed by the pod
kube-system          46s         Normal    Created                   pod/calico-node-nmr4f                                            Container created
kube-system          45s         Warning   Unhealthy                 pod/calico-node-blglx                                            Readiness probe failed: calico/node is not ready: BIRD is not ready: failed to stat() nodename file: stat /var/lib/calico/nodename: no such file or directory
kube-system          45s         Normal    Started                   pod/calico-node-c2jhk                                            Container started
kube-system          44s         Warning   Unhealthy                 pod/calico-node-nmr4f                                            Readiness probe failed: calico/node is not ready: BIRD is not ready: error querying BIRD: unable to connect to BIRDv4 socket: dial unix /var/run/bird/bird.ctl: connect: no such file or directory
kube-system          45s         Normal    Created                   pod/calico-node-c2jhk                                            Container created
kube-system          44s         Warning   Unhealthy                 pod/calico-node-hfqqw                                            Readiness probe failed: calico/node is not ready: BIRD is not ready: error querying BIRD: unable to connect to BIRDv4 socket: dial unix /var/run/bird/bird.ctl: connect: no such file or directory
kube-system          45s         Normal    Pulled                    pod/calico-node-c2jhk                                            Container image "quay.io/calico/node@sha256:7f874b3f0b540c2b523aea9961ef5e2f43b0af9056a47874c916d6cf348168d3" already present on machine and can be accessed by the pod
kube-system          44s         Warning   Unhealthy                 pod/calico-node-blglx                                            Readiness probe failed: calico/node is not ready: BIRD is not ready: error querying BIRD: unable to connect to BIRDv4 socket: dial unix /var/run/bird/bird.ctl: connect: no such file or directory
kube-system          43s         Warning   Unhealthy                 pod/calico-node-c2jhk                                            Readiness probe failed: calico/node is not ready: BIRD is not ready: error querying BIRD: unable to connect to BIRDv4 socket: dial unix /var/run/bird/bird.ctl: connect: no such file or directory
default              42s         Normal    NodeReady                 node/article3-performance-worker3                                Node article3-performance-worker3 status is now: NodeReady
kube-system          41s         Normal    Scheduled                 pod/coredns-7d764666f9-d44n9                                     Successfully assigned kube-system/coredns-7d764666f9-d44n9 to article3-performance-worker3
local-path-storage   41s         Normal    Scheduled                 pod/local-path-provisioner-67b8995b4b-7hc8p                      Successfully assigned local-path-storage/local-path-provisioner-67b8995b4b-7hc8p to article3-performance-worker3
kube-system          41s         Normal    Scheduled                 pod/calico-kube-controllers-77bdb5dddb-mnzxq                     Successfully assigned kube-system/calico-kube-controllers-77bdb5dddb-mnzxq to article3-performance-worker3
kube-system          41s         Normal    Scheduled                 pod/coredns-7d764666f9-j5lb8                                     Successfully assigned kube-system/coredns-7d764666f9-j5lb8 to article3-performance-worker3
default              40s         Normal    NodeReady                 node/article3-performance-control-plane                          Node article3-performance-control-plane status is now: NodeReady
default              40s         Normal    NodeReady                 node/article3-performance-worker                                 Node article3-performance-worker status is now: NodeReady
default              40s         Normal    NodeReady                 node/article3-performance-worker2                                Node article3-performance-worker2 status is now: NodeReady
kube-system          39s         Normal    Created                   pod/calico-kube-controllers-77bdb5dddb-mnzxq                     Container created
kube-system          39s         Normal    Pulled                    pod/coredns-7d764666f9-d44n9                                     Container image "registry.k8s.io/coredns/coredns:v1.13.1" already present on machine and can be accessed by the pod
local-path-storage   39s         Normal    Pulled                    pod/local-path-provisioner-67b8995b4b-7hc8p                      Container image "docker.io/kindest/local-path-provisioner:v20251212-v0.29.0-alpha-105-g20ccfc88" already present on machine and can be accessed by the pod
kube-system          39s         Normal    Pulled                    pod/calico-kube-controllers-77bdb5dddb-mnzxq                     Container image "quay.io/calico/kube-controllers@sha256:18008f781c869376dbbc4dfb1ffe3afb46f7897887d4f20e080c420ac44a6612" already present on machine and can be accessed by the pod
kube-system          39s         Normal    Pulled                    pod/coredns-7d764666f9-j5lb8                                     Container image "registry.k8s.io/coredns/coredns:v1.13.1" already present on machine and can be accessed by the pod
kube-system          39s         Normal    Started                   pod/calico-kube-controllers-77bdb5dddb-mnzxq                     Container started
kube-system          36s         Normal    Created                   pod/coredns-7d764666f9-j5lb8                                     Container created
kube-system          36s         Normal    Started                   pod/coredns-7d764666f9-j5lb8                                     Container started
kube-system          36s         Normal    Started                   pod/coredns-7d764666f9-d44n9                                     Container started
kube-system          36s         Normal    Created                   pod/coredns-7d764666f9-d44n9                                     Container created
local-path-storage   35s         Normal    Started                   pod/local-path-provisioner-67b8995b4b-7hc8p                      Container started
local-path-storage   35s         Normal    Created                   pod/local-path-provisioner-67b8995b4b-7hc8p                      Container created
article3-cni-check   23s         Normal    Scheduled                 pod/server                                                       Successfully assigned article3-cni-check/server to article3-performance-worker
article3-cni-check   22s         Normal    Scheduled                 pod/client                                                       Successfully assigned article3-cni-check/client to article3-performance-worker2
article3-cni-check   21s         Normal    Pulling                   pod/server                                                       Pulling image "docker.io/library/busybox@sha256:9532d8c39891ca2ecde4d30d7710e01fb739c87a8b9299685c63704296b16028"
article3-cni-check   20s         Normal    Pulling                   pod/client                                                       Pulling image "docker.io/library/busybox@sha256:9532d8c39891ca2ecde4d30d7710e01fb739c87a8b9299685c63704296b16028"
article3-cni-check   12s         Normal    Created                   pod/client                                                       Container created
article3-cni-check   12s         Normal    Pulled                    pod/client                                                       Successfully pulled image "docker.io/library/busybox@sha256:9532d8c39891ca2ecde4d30d7710e01fb739c87a8b9299685c63704296b16028" in 8.389s (8.389s including waiting). Image size: 2222111 bytes.
article3-cni-check   11s         Normal    Started                   pod/server                                                       Container started
article3-cni-check   11s         Normal    Started                   pod/client                                                       Container started
article3-cni-check   11s         Normal    Pulled                    pod/server                                                       Successfully pulled image "docker.io/library/busybox@sha256:9532d8c39891ca2ecde4d30d7710e01fb739c87a8b9299685c63704296b16028" in 9.882s (9.882s including waiting). Image size: 2222111 bytes.
article3-cni-check   11s         Normal    Created                   pod/server                                                       Container created
